<mujoco>
  <asset>
    <texture name="grid" type="2d" builtin="checker" rgb1=".1 .2 .3"
     rgb2=".2 .3 .4" width="300" height="300" mark="none"/>
    <material name="grid" texture="grid" texrepeat="6 6"
     texuniform="true" reflectance=".1"/>
     <material name="wall" rgba='.5 .5 .5 1'/>
  </asset>


  <worldbody>
    <light name="light" pos="-.2 0 1"/>
    <geom name="ground" type="plane" size=".5 .5 10" material="grid"
     zaxis="0 0 1" friction=".2"/>

    <body name="cart"  pos="0 0 .05" >
      <joint name = "x_joint" type="slide"  axis="1 0 0"/>
      <joint name = "z_joint" type="slide"  axis="0 0 1"/>
      <geom name="red_box" type="box" size=".05 .05 .05" 
      friction="0.33" rgba="1 0 0 1"/>
      <site name="IMU"/>
    </body>

    <body name="target"  pos="0 0 0">
      <geom name="green_sphere" pos="0 -0.05 0" size=".01" rgba="0 1 0 1"
      contype="0" conaffinity="0"/>
      <joint name = "t_joint" type="slide"  axis="1 0 0"/>
    </body>
    
  </worldbody>

  <keyframe>
    <key name="exp1" qpos="-0.6 0 0" qvel="3 0 0"/>
  </keyframe>

  <sensor>
    <framepos name="sensor" objtype="xbody" objname="cart"/>
  </sensor>

  <actuator>
        <motor name="actuator" joint="x_joint" gear="1.5" />
    </actuator>

</mujoco>